# promise, async, await
## 콜백
- 인자로 넘겨져 나중에 호출되는(callback) 함수
- 첫 번째 인자는 에러를 위해 사용되는게 관례
```js
asyncFunction(ayncArg, function(error, ...arg) {
  if (error) {
    // 에러 처리
  } 
  else {
    // 대충 콜백으로 실행될 내용들
  }
});
```
### pyramid of doom(callback hell)
- 콜백 기반 비동기 처리를 위해 계속해서 콜백을 타고타고 들어가 관리가 어려워짐
![callback_hell](https://ko.javascript.info/article/callbacks/callback-hell.svg)
- 각 동작을 동립적인 함수로 만들어 해결해도 되지만 가독성도 안좋고 재사용도 어려움
```js
loadScript('1.js', step1);

function step1(error, script) {
  if (error) {
    handleError(error);
  } else {
    // ...
    loadScript('2.js', step2);
  }
}

function step2(error, script) {
  if (error) {
    handleError(error);
  } else {
    // ...
    loadScript('3.js', step3);
  }
}

function step3(error, script) {
  if (error) {
    handleError(error);
  } else {
    // 모든 스크립트가 로딩되면 수행
  }
};
```

## Promise
- `new Promise`에 인자로 넘어가는 함수를 executor라고 함
- `new Promise`생성자가 반환하는 객체에는 `state`, `result` property가 있음
![상태](https://ko.javascript.info/article/promise-chaining/promise-handler-variants.svg)
```js
new Promise((resolve, reject) => {
  ...
})
  .finally(() => alert("결과는 finally를 그냥 통과해서 전달됨"))
  .then(result => alert(result))    // result 처리
  .catch(err => alert(err)) // err 처리
  .then(someFunction, errorHandler) // then에서도 2번째 인자로 에러처리 가능함
  .finally(() => alert("보편적인 일을 하자"))
```
- `then`에서의 2번째 인자로 받는 에러처리는 해당 `then`에서 발생하는 에러(예: `someFunction`에서 에러)는 처리할 수 없음
- `finally`는 promise 성공/실패 여부 상관없이 진행되며 핸들러에는 인수도 없음
- 위 예제의 체이닝이 가능한 건 `result`, `error`을 전달하면서 promise 다시 반환하기 때문.
    - `.then(handler)`에서 `handler`함수가 promise를 다시 반환할 수도 있다.(resolve 함수 호출)
    - `handler`함수는 promise와 호환 가능한 `thenable`객체(`then`메소드 보유)를 반환 할 수도
        ```JS
            // Promise를 상속받지 않은 커스텀 Thenable 클래스
            class Thenable {
                constructor(num) {
                    this.num = num;
                }
                then(resolve, reject) {
                    alert(resolve); // function() { 네이티브 코드 }
                    setTimeout(() => resolve(this.num * 2), 1000); // (**)
                }
            }

            new Promise(resolve => resolve(1))
            .then(result => {
                return new Thenable(result); // (*)
            })
            .then(alert); // 1초 후 2를 보여줌
        ```
## promise 에러 핸들링
- `rejection` -> 제일 가까운 `rejection` 핸들러로 넘어감
- 에러를 `throw`로 날려도 `rejection`으로 봄
```js
fetch('https://no-such-server.blabla') // 실패 발생
  .then(...)
  .then(response => response.json())
  .catch(...) // 에러처리
  .then(...) // catch에서 에러 잘처리했으면 실행
  .catch(...) // 위에서 에러처리 다 안되고 다시 던지면 실행
```
- 에러는 있는데 `then`만 주구장창 체인걸어두고 `catch` 안잡아두면 js엔진은 promise rejection 추적하다가 전역 에러 생성
    - unhandledrejection 이벤트로 잡을 수 있음(HTML 명세서에 정의된 표준)
        ```js
        window.addEventListener('unhandledrejection', function(event) {
        // 이벤트엔 두 개의 특별 프로퍼티 보유
        alert(event.promise); // [object Promise] - 에러를 생성하는 프라미스
        alert(event.reason); // Error: 에러 발생! - 처리하지 못한 에러 객체
        });

        new Promise(function() {
        throw new Error("에러 발생!");
        }); // 에러 처리 핸들러, catch가 없음
        ```
    - 보통 이런 에러는 회복이 어렵기 때문에 걍 사용자에게 문제를 알리고 서버로 에러정보 보냄
- `catch`는 비동기적 에러를 못잡아낸다. 아래 케이스 죄다 못잡음;
    ```js
    new Promise(function(resolve, reject) {
        setTimeout(() => {
            throw new Error("에러 발생!");
        }, 1000);
    }).catch(alert);

    new Promise(function(resolve, reject) { resolve(1) })
        .then((result) => {
            console.log(result)
            setTimeout(() => {
            throw new Error("에러 발생!");
            }, 1000);
        })
        .catch(alert);
    ```
## Promise api
### Promise.all
- 여러 promise를 실행시키고 완료될 때 `result`들의 배열을 전달하는 promise 반환
```js
// promise객체들의 배열 or iterable을 받음
Promise.all([
  new Promise(resolve => setTimeout(() => resolve(1), 3000)),
  new Promise(resolve => setTimeout(() => resolve(2), 2000)),
  new Promise(resolve => setTimeout(() => resolve(3), 1000)),
  4                   // 일반 값도 그냥 넣을 수 있음.
]).then(console.log)  // 정상 실행시 result = [1, 2, 3, 4], 실행시간이 아닌 인자 순서에 따라 정렬됨.
  .catch(console.log); // 3개중 하나라도 에러터지면 다른 promise result들 무시하고 작동
```

### Promise.allSettled
- `.all`과 달리 모든 promise가 실패든 성공이든 처리될 때까지 기다림. 반환되는 배열의 요소는 다음과 같음
  - 응답이 성공할 경우 – {status:"fulfilled", value:result}
  - 에러가 발생한 경우 – {status:"rejected", reason:error}
- 구식 브라우저 polyfill 필요
```js
if(!Promise.allSettled) {
  Promise.allSettled = function(promises) {
    return Promise.all(promises.map(p => Promise.resolve(p).then(value => ({
      status: 'fulfilled',
      value
    }), reason => ({
      status: 'rejected',
      reason
    }))));
  };
}
```

### Promise.race
- `.all`과 비슷하지만 가장 먼저 처리되는 결과/에러를 반환

### Promise.resolve/reject
- async/await 문법땜시 거의 안쓰이는 중
- `Promise.resolve(value)`는 `new Promise(resolve => resolve(value))`와 동일
- `Promise.reject(error)`는 `new Promise((resolve, reject) => reject(error))`와 동일
- 호환성을 위해 함수가 promise를 반환해야 사용 가능

## promisification
- 콜백 받는 함수 -> promise반환하는 함수로 바꾸는 것
```js
// 콜백의 성공 결과를 담은 배열을 얻게 해주는 promisify(f, true)
function promisify(f, manyArgs = false) {
  // promise를 반환하기 위한  wrapper 함수
  return function (...args) {
    return new Promise((resolve, reject) => {
      function callback(err, ...results) { // f에 사용할 커스텀 콜백
        if (err) {
          reject(err);
        } else {
          resolve(manyArgs ? results : results[0]);
        }
      }
      // 원본함수 마지막 인자에 reject/resolve 때리는 콜백 전달
      args.push(callback);
      // 원본함수 실행
      f.call(this, ...args);
    });
  };
};

// 사용법:
f = promisify(f, true);
f(...).then(arrayOfResults => ..., err => ...)
```

## 마이크로태스크
- 비동기 작업들(예: `.then`, `.catch`, `.finally`) 관리를 위해 ECMA에서는 마이크로태스크 큐(v8엔진ver, PromiseJobs라고도 함) 사용
  - FIFO
  - 실행할 것이 없을 때만(다른 코드 전부 실행 후) 마이크로태스크 큐의 작업들이 실행됨

### [unhandledrejection](#promise-에러-핸들링)
- 마이크로태스크 큐 끝에서 promise 에러가 처리되지 못할 때 발생(개발자가 `.catch` 안하면 발생한다)
- 만약 `setTimeout`으로 일부러 에러를 나중에 처리한다면?
  ```js
  let promise = Promise.reject(new Error("프라미스 실패!"));
  setTimeout(() => promise.catch(err => alert('잡았다!')), 1000);

  // Error: 프라미스 실패!
  window.addEventListener('unhandledrejection', event => alert(event.reason));
  ```
  - **프라미스 실패!**가 **잡았다!**보다 먼자 출력됨.
    - 마이크로태스크 큐에 있는 작업이 모두 완료되었을 때 `unhandledrejection` 생성
    - `setTimeout`을 사용해 추가한 `.catch`는 `unhandledrejection`가 발생 한 후에 트리거되므로 실패 문자열이 먼저 뜬다.

## async와 await
- `await`는 `async`함수 내에서만 사용
```js
// promise 반환
async function f() {

  let promise = new Promise((resolve, reject) => {
    setTimeout(() => resolve("완료!"), 1000)
  });
  // promise가 settled될때까지 대기. js엔진은 그동안 다른일 함.
  let result = await promise; 

  return result;
}

f().then((result) => console.log(result)); // 완료
```
- `await`는 최상위 레벨 코드에서 에러남(지원하는데도 있긴한데 자제하자)
```js
// 에러 발생
// let response = await fetch('/article/promise-chaining/user.json');
// let user = await response.json();

// 꼼수로 실행 가능하긴 함.
(async () => {
  let response = await fetch('/article/promise-chaining/user.json');
  let user = await response.json();
  ...
})();
```
- `await`는 `thenable`객체를 받으면 `then`메소드를 실행하고 결과/에러를 받아옴
```js
class Thenable {
  constructor(num) {
    this.num = num;
  }
  then(resolve, reject) {
    alert(resolve);
    setTimeout(() => resolve(this.num * 2), 1000); // (*)
  }
};

async function f() {
  let result = await new Thenable(1);
  alert(result);
}

f();  // 2
```

### 에러 핸들링
- `async`함수 내에서 `await Promise.reject(new Error(...))`는 `throw new Error(...)`와 동일
- `async/await` 쓰니까 `then/catch` 잘 안쓰게됨(최상 레벨 코드빼고) 대신 `try..catch`로 에러 처리
(`try..catch`안쓰고 `f().catch`로 에러 잡아도 되긴함)
  ```js
  async function f() {

    try {
      let response = await fetch('http://유효하지-않은-주소');
    } catch(err) {
      alert(err); // TypeError: failed to fetch
    }
  }

  f();

  // promise api랑도 잘 어울림
  let results = await Promise.all([
    fetch(url1),
    fetch(url2),
    ...
  ]);  
  ```